File: data.csv
[Measurement conditions]
Sample identification,
Comment - 1,"Configuration=TST, Owner=User-1, Creation date=12/09/2013 10:03:47"
Comment - 2,"Goniometer=PW3050/65 (Theta/2Theta); Minimum step size 2Theta:0,0001; Minimum step size Omega:0,0001"
Comment - 3,"Sample stage=MRD XL Cradle; Minimum step size Phi:0,01; Minimum step size Chi:0,01; Minimum step size X:0,01; Minimum step size Y:0,01; Minimum step size Z:0,001"
Comment - 4,"Diffractometer system=XPERT-PRO"
Comment - 5,"Measurement program=20170921_miscut_w3_0.01_phi360_15_0.1s, Owner=User-1, Creation date=22/09/2017 16:30:35"
Anode material,Co
K-Alpha1 wavelength,1.7890100
K-Alpha2 wavelength,1.7929000
Ratio K-Alpha2/K-Alpha1,0.500
Divergence slit,Fixed,0.76mm
Receiving slit,0.10
Monochromator used,YES
Generator voltage, 40
Tube current, 45
File date and time,13/abr/2018 16:39
Unit cell,
h k l, 0 0 0
No. of scans, 24
Measurement step axis,Phi
Measurement step axis range,0.00,345.00,15.00
Scan axis,Omega
Scan range,25.7750,28.7650,0.0100000
No. of points per scan, 299
Scan type,CONTINUOUS
2Theta,54.5400
Psi,0.00
X,-1.12
Y,1.17
Z,4.312
Time per step,0.10
[Scan points]
Omega position, Phi position, Intensity
25.7800,0.00,0
25.8300,0.00,0
25.8800,0.00,0
25.9300,0.00,0
25.9800,0.00,0
26.0300,0.00,0
26.0800,0.00,0
26.1300,0.00,0
26.1800,0.00,0
26.2300,0.00,1
26.2800,0.00,0
26.3300,0.00,0
26.3800,0.00,0
26.4300,0.00,0
26.4800,0.00,0
26.5300,0.00,0
26.5800,0.00,1
26.6300,0.00,0
26.6800,0.00,1
26.7300,0.00,0
26.7800,0.00,0
26.8300,0.00,0
26.8800,0.00,0
26.9300,0.00,0
26.9800,0.00,2
27.0300,0.00,6
27.0800,0.00,40
27.1300,0.00,10
27.1800,0.00,11
27.2300,0.00,28
27.2800,0.00,47
27.3300,0.00,33
27.3800,0.00,6
27.4300,0.00,6
27.4800,0.00,7
27.5300,0.00,16
27.5800,0.00,48
27.6300,0.00,621
27.6800,0.00,810
27.7300,0.00,714
27.7800,0.00,297
27.8300,0.00,177
27.8800,0.00,104
27.9300,0.00,97
27.9800,0.00,76
28.0300,0.00,163
28.0800,0.00,95
28.1300,0.00,39
28.1800,0.00,5
28.2300,0.00,0
28.2800,0.00,0
28.3300,0.00,1
28.3800,0.00,0
28.4300,0.00,0
28.4800,0.00,0
28.5300,0.00,0
28.5800,0.00,0
28.6300,0.00,0
28.6800,0.00,0
28.7300,0.00,0
25.7900,15.00,0
25.8400,15.00,0
25.8900,15.00,0
25.9400,15.00,0
25.9900,15.00,0
26.0400,15.00,0
26.0900,15.00,0
26.1400,15.00,0
26.1900,15.00,0
26.2400,15.00,0
26.2900,15.00,0
26.3400,15.00,0
26.3900,15.00,0
26.4400,15.00,0
26.4900,15.00,0
26.5400,15.00,0
26.5900,15.00,0
26.6400,15.00,0
26.6900,15.00,0
26.7400,15.00,1
26.7900,15.00,0
26.8400,15.00,0
26.8900,15.00,0
26.9400,15.00,0
26.9900,15.00,3
27.0400,15.00,1
27.0900,15.00,2
27.1400,15.00,18
27.1900,15.00,5
27.2400,15.00,3
27.2900,15.00,9
27.3400,15.00,17
27.3900,15.00,9
27.4400,15.00,20
27.4900,15.00,38
27.5400,15.00,80
27.5900,15.00,568
27.6400,15.00,329
27.6900,15.00,676
27.7400,15.00,587
27.7900,15.00,289
27.8400,15.00,277
27.8900,15.00,172
27.9400,15.00,185
27.9900,15.00,54
28.0400,15.00,13
28.0900,15.00,0
28.1400,15.00,1
28.1900,15.00,0
28.2400,15.00,2
28.2900,15.00,0
28.3400,15.00,0
28.3900,15.00,0
28.4400,15.00,0
28.4900,15.00,0
28.5400,15.00,1
28.5900,15.00,0
28.6400,15.00,0
28.6900,15.00,1
28.7400,15.00,0
25.8000,30.00,0
25.8500,30.00,0
25.9000,30.00,0
25.9500,30.00,1
26.0000,30.00,0
26.0500,30.00,0
26.1000,30.00,0
26.1500,30.00,0
26.2000,30.00,0
26.2500,30.00,0
26.3000,30.00,0
26.3500,30.00,0
26.4000,30.00,0
26.4500,30.00,0
26.5000,30.00,0
26.5500,30.00,0
26.6000,30.00,0
26.6500,30.00,0
26.7000,30.00,0
26.7500,30.00,0
26.8000,30.00,0
26.8500,30.00,0
26.9000,30.00,0
26.9500,30.00,0
27.0000,30.00,0
27.0500,30.00,1
27.1000,30.00,1
27.1500,30.00,1
27.2000,30.00,1
27.2500,30.00,16
27.3000,30.00,19
27.3500,30.00,10
27.4000,30.00,19
27.4500,30.00,81
27.5000,30.00,497
27.5500,30.00,240
27.6000,30.00,186
27.6500,30.00,703
27.7000,30.00,1029
27.7500,30.00,499
27.8000,30.00,144
27.8500,30.00,42
27.9000,30.00,6
27.9500,30.00,1
28.0000,30.00,1
28.0500,30.00,1
28.1000,30.00,0
28.1500,30.00,1
28.2000,30.00,0
28.2500,30.00,0
28.3000,30.00,0
28.3500,30.00,0
28.4000,30.00,1
28.4500,30.00,0
28.5000,30.00,0
28.5500,30.00,0
28.6000,30.00,0
28.6500,30.00,0
28.7000,30.00,0
28.7500,30.00,0
25.8100,45.00,0
25.8600,45.00,0
25.9100,45.00,0
25.9600,45.00,0
26.0100,45.00,0
26.0600,45.00,0
26.1100,45.00,0
26.1600,45.00,0
26.2100,45.00,2
26.2600,45.00,1
26.3100,45.00,0
26.3600,45.00,1
26.4100,45.00,1
26.4600,45.00,7
26.5100,45.00,7
26.5600,45.00,6
26.6100,45.00,4
26.6600,45.00,2
26.7100,45.00,0
26.7600,45.00,2
26.8100,45.00,0
26.8600,45.00,2
26.9100,45.00,20
26.9600,45.00,5
27.0100,45.00,0
27.0600,45.00,6
27.1100,45.00,2
27.1600,45.00,13
27.2100,45.00,25
27.2600,45.00,24
27.3100,45.00,33
27.3600,45.00,371
27.4100,45.00,201
27.4600,45.00,134
27.5100,45.00,187
27.5600,45.00,331
27.6100,45.00,1308
27.6600,45.00,565
27.7100,45.00,141
27.7600,45.00,13
27.8100,45.00,5
27.8600,45.00,1
27.9100,45.00,2
27.9600,45.00,2
28.0100,45.00,1
28.0600,45.00,0
28.1100,45.00,0
28.1600,45.00,0
28.2100,45.00,0
28.2600,45.00,0
28.3100,45.00,0
28.3600,45.00,0
28.4100,45.00,0
28.4600,45.00,0
28.5100,45.00,0
28.5600,45.00,0
28.6100,45.00,0
28.6600,45.00,0
28.7100,45.00,0
28.7600,45.00,0
25.8200,60.00,1
25.8700,60.00,0
25.9200,60.00,3
25.9700,60.00,1
26.0200,60.00,2
26.0700,60.00,3
26.1200,60.00,0
26.1700,60.00,1
26.2200,60.00,0
26.2700,60.00,3
26.3200,60.00,5
26.3700,60.00,6
26.4200,60.00,10
26.4700,60.00,9
26.5200,60.00,2
26.5700,60.00,2
26.6200,60.00,1
26.6700,60.00,0
26.7200,60.00,0
26.7700,60.00,1
26.8200,60.00,5
26.8700,60.00,4
26.9200,60.00,2
26.9700,60.00,2
27.0200,60.00,3
27.0700,60.00,1
27.1200,60.00,11
27.1700,60.00,22
27.2200,60.00,190
27.2700,60.00,189
27.3200,60.00,104
27.3700,60.00,105
27.4200,60.00,236
27.4700,60.00,597
27.5200,60.00,1525
27.5700,60.00,495
27.6200,60.00,77
27.6700,60.00,6
27.7200,60.00,3
27.7700,60.00,1
27.8200,60.00,1
27.8700,60.00,0
27.9200,60.00,1
27.9700,60.00,0
28.0200,60.00,1
28.0700,60.00,0
28.1200,60.00,0
28.1700,60.00,0
28.2200,60.00,0
28.2700,60.00,1
28.3200,60.00,0
28.3700,60.00,0
28.4200,60.00,0
28.4700,60.00,0
28.5200,60.00,0
28.5700,60.00,0
28.6200,60.00,0
28.6700,60.00,0
28.7200,60.00,0
25.7800,75.00,0
25.8300,75.00,0
25.8800,75.00,0
25.9300,75.00,0
25.9800,75.00,0
26.0300,75.00,0
26.0800,75.00,0
26.1300,75.00,1
26.1800,75.00,2
26.2300,75.00,2
26.2800,75.00,5
26.3300,75.00,6
26.3800,75.00,0
26.4300,75.00,4
26.4800,75.00,3
26.5300,75.00,2
26.5800,75.00,0
26.6300,75.00,0
26.6800,75.00,0
26.7300,75.00,2
26.7800,75.00,5
26.8300,75.00,1
26.8800,75.00,2
26.9300,75.00,1
26.9800,75.00,5
27.0300,75.00,7
27.0800,75.00,36
27.1300,75.00,254
27.1800,75.00,132
27.2300,75.00,29
27.2800,75.00,148
27.3300,75.00,379
27.3800,75.00,1118
27.4300,75.00,709
27.4800,75.00,208
27.5300,75.00,26
27.5800,75.00,1
27.6300,75.00,0
27.6800,75.00,1
27.7300,75.00,0
27.7800,75.00,0
27.8300,75.00,0
27.8800,75.00,0
27.9300,75.00,0
27.9800,75.00,0
28.0300,75.00,1
28.0800,75.00,0
28.1300,75.00,0
28.1800,75.00,0
28.2300,75.00,0
28.2800,75.00,0
28.3300,75.00,0
28.3800,75.00,0
28.4300,75.00,0
28.4800,75.00,0
28.5300,75.00,0
28.5800,75.00,0
28.6300,75.00,0
28.6800,75.00,1
28.7300,75.00,0
25.7900,90.00,0
25.8400,90.00,0
25.8900,90.00,0
25.9400,90.00,0
25.9900,90.00,0
26.0400,90.00,0
26.0900,90.00,0
26.1400,90.00,0
26.1900,90.00,0
26.2400,90.00,0
26.2900,90.00,0
26.3400,90.00,0
26.3900,90.00,0
26.4400,90.00,0
26.4900,90.00,0
26.5400,90.00,0
26.5900,90.00,0
26.6400,90.00,1
26.6900,90.00,2
26.7400,90.00,4
26.7900,90.00,10
26.8400,90.00,8
26.8900,90.00,5
26.9400,90.00,23
26.9900,90.00,200
27.0400,90.00,166
27.0900,90.00,62
27.1400,90.00,63
27.1900,90.00,322
27.2400,90.00,701
27.2900,90.00,1176
27.3400,90.00,483
27.3900,90.00,113
27.4400,90.00,7
27.4900,90.00,5
27.5400,90.00,2
27.5900,90.00,1
27.6400,90.00,0
27.6900,90.00,0
27.7400,90.00,0
27.7900,90.00,0
27.8400,90.00,1
27.8900,90.00,1
27.9400,90.00,0
27.9900,90.00,0
28.0400,90.00,0
28.0900,90.00,0
28.1400,90.00,0
28.1900,90.00,0
28.2400,90.00,0
28.2900,90.00,0
28.3400,90.00,0
28.3900,90.00,0
28.4400,90.00,0
28.4900,90.00,0
28.5400,90.00,0
28.5900,90.00,0
28.6400,90.00,0
28.6900,90.00,0
28.7400,90.00,0
25.8000,105.00,0
25.8500,105.00,0
25.9000,105.00,0
25.9500,105.00,0
26.0000,105.00,0
26.0500,105.00,0
26.1000,105.00,0
26.1500,105.00,0
26.2000,105.00,0
26.2500,105.00,0
26.3000,105.00,1
26.3500,105.00,0
26.4000,105.00,0
26.4500,105.00,2
26.5000,105.00,8
26.5500,105.00,16
26.6000,105.00,9
26.6500,105.00,10
26.7000,105.00,13
26.7500,105.00,11
26.8000,105.00,15
26.8500,105.00,47
26.9000,105.00,110
26.9500,105.00,115
27.0000,105.00,112
27.0500,105.00,233
27.1000,105.00,345
27.1500,105.00,852
27.2000,105.00,721
27.2500,105.00,350
27.3000,105.00,47
27.3500,105.00,4
27.4000,105.00,7
27.4500,105.00,7
27.5000,105.00,3
27.5500,105.00,0
27.6000,105.00,0
27.6500,105.00,0
27.7000,105.00,0
27.7500,105.00,0
27.8000,105.00,0
27.8500,105.00,0
27.9000,105.00,0
27.9500,105.00,0
28.0000,105.00,0
28.0500,105.00,0
28.1000,105.00,0
28.1500,105.00,0
28.2000,105.00,0
28.2500,105.00,0
28.3000,105.00,0
28.3500,105.00,1
28.4000,105.00,0
28.4500,105.00,0
28.5000,105.00,0
28.5500,105.00,0
28.6000,105.00,0
28.6500,105.00,0
28.7000,105.00,0
28.7500,105.00,0
25.8100,120.00,0
25.8600,120.00,0
25.9100,120.00,0
25.9600,120.00,0
26.0100,120.00,0
26.0600,120.00,0
26.1100,120.00,0
26.1600,120.00,0
26.2100,120.00,0
26.2600,120.00,1
26.3100,120.00,0
26.3600,120.00,12
26.4100,120.00,21
26.4600,120.00,7
26.5100,120.00,27
26.5600,120.00,10
26.6100,120.00,17
26.6600,120.00,25
26.7100,120.00,16
26.7600,120.00,35
26.8100,120.00,65
26.8600,120.00,140
26.9100,120.00,249
26.9600,120.00,196
27.0100,120.00,336
27.0600,120.00,894
27.1100,120.00,807
27.1600,120.00,381
27.2100,120.00,61
27.2600,120.00,7
27.3100,120.00,9
27.3600,120.00,27
27.4100,120.00,12
27.4600,120.00,9
27.5100,120.00,2
27.5600,120.00,3
27.6100,120.00,3
27.6600,120.00,1
27.7100,120.00,1
27.7600,120.00,0
27.8100,120.00,0
27.8600,120.00,0
27.9100,120.00,0
27.9600,120.00,0
28.0100,120.00,0
28.0600,120.00,1
28.1100,120.00,0
28.1600,120.00,0
28.2100,120.00,0
28.2600,120.00,0
28.3100,120.00,0
28.3600,120.00,0
28.4100,120.00,0
28.4600,120.00,0
28.5100,120.00,0
28.5600,120.00,0
28.6100,120.00,0
28.6600,120.00,0
28.7100,120.00,0
28.7600,120.00,0
25.8200,135.00,0
25.8700,135.00,0
25.9200,135.00,1
25.9700,135.00,0
26.0200,135.00,0
26.0700,135.00,2
26.1200,135.00,0
26.1700,135.00,0
26.2200,135.00,3
26.2700,135.00,5
26.3200,135.00,11
26.3700,135.00,38
26.4200,135.00,20
26.4700,135.00,36
26.5200,135.00,29
26.5700,135.00,35
26.6200,135.00,30
26.6700,135.00,23
26.7200,135.00,42
26.7700,135.00,77
26.8200,135.00,240
26.8700,135.00,252
26.9200,135.00,374
26.9700,135.00,778
27.0200,135.00,1102
27.0700,135.00,569
27.1200,135.00,138
27.1700,135.00,28
27.2200,135.00,3
27.2700,135.00,12
27.3200,135.00,30
27.3700,135.00,55
27.4200,135.00,16
27.4700,135.00,4
27.5200,135.00,6
27.5700,135.00,14
27.6200,135.00,7
27.6700,135.00,2
27.7200,135.00,0
27.7700,135.00,0
27.8200,135.00,1
27.8700,135.00,1
27.9200,135.00,1
27.9700,135.00,0
28.0200,135.00,0
28.0700,135.00,0
28.1200,135.00,0
28.1700,135.00,0
28.2200,135.00,0
28.2700,135.00,0
28.3200,135.00,0
28.3700,135.00,0
28.4200,135.00,0
28.4700,135.00,0
28.5200,135.00,0
28.5700,135.00,0
28.6200,135.00,0
28.6700,135.00,0
28.7200,135.00,0
25.7800,150.00,0
25.8300,150.00,0
25.8800,150.00,0
25.9300,150.00,0
25.9800,150.00,0
26.0300,150.00,0
26.0800,150.00,0
26.1300,150.00,0
26.1800,150.00,0
26.2300,150.00,2
26.2800,150.00,2
26.3300,150.00,15
26.3800,150.00,34
26.4300,150.00,42
26.4800,150.00,72
26.5300,150.00,24
26.5800,150.00,41
26.6300,150.00,37
26.6800,150.00,54
26.7300,150.00,94
26.7800,150.00,184
26.8300,150.00,185
26.8800,150.00,493
26.9300,150.00,956
26.9800,150.00,949
27.0300,150.00,336
27.0800,150.00,51
27.1300,150.00,3
27.1800,150.00,5
27.2300,150.00,4
27.2800,150.00,8
27.3300,150.00,18
27.3800,150.00,21
27.4300,150.00,9
27.4800,150.00,7
27.5300,150.00,9
27.5800,150.00,30
27.6300,150.00,9
27.6800,150.00,1
27.7300,150.00,0
27.7800,150.00,0
27.8300,150.00,2
27.8800,150.00,0
27.9300,150.00,0
27.9800,150.00,1
28.0300,150.00,1
28.0800,150.00,0
28.1300,150.00,0
28.1800,150.00,1
28.2300,150.00,0
28.2800,150.00,0
28.3300,150.00,0
28.3800,150.00,0
28.4300,150.00,0
28.4800,150.00,0
28.5300,150.00,0
28.5800,150.00,0
28.6300,150.00,0
28.6800,150.00,1
28.7300,150.00,0
25.7900,165.00,0
25.8400,165.00,0
25.8900,165.00,0
25.9400,165.00,0
25.9900,165.00,0
26.0400,165.00,0
26.0900,165.00,1
26.1400,165.00,0
26.1900,165.00,0
26.2400,165.00,0
26.2900,165.00,3
26.3400,165.00,2
26.3900,165.00,9
26.4400,165.00,71
26.4900,165.00,68
26.5400,165.00,49
26.5900,165.00,41
26.6400,165.00,37
26.6900,165.00,35
26.7400,165.00,176
26.7900,165.00,136
26.8400,165.00,267
26.8900,165.00,777
26.9400,165.00,1405
26.9900,165.00,568
27.0400,165.00,150
27.0900,165.00,11
27.1400,165.00,2
27.1900,165.00,1
27.2400,165.00,2
27.2900,165.00,10
27.3400,165.00,5
27.3900,165.00,6
27.4400,165.00,5
27.4900,165.00,2
27.5400,165.00,2
27.5900,165.00,9
27.6400,165.00,2
27.6900,165.00,0
27.7400,165.00,0
27.7900,165.00,0
27.8400,165.00,0
27.8900,165.00,1
27.9400,165.00,0
27.9900,165.00,0
28.0400,165.00,0
28.0900,165.00,0
28.1400,165.00,0
28.1900,165.00,0
28.2400,165.00,0
28.2900,165.00,0
28.3400,165.00,0
28.3900,165.00,0
28.4400,165.00,0
28.4900,165.00,0
28.5400,165.00,0
28.5900,165.00,0
28.6400,165.00,0
28.6900,165.00,0
28.7400,165.00,0
25.8000,180.00,0
25.8500,180.00,0
25.9000,180.00,0
25.9500,180.00,0
26.0000,180.00,0
26.0500,180.00,0
26.1000,180.00,0
26.1500,180.00,0
26.2000,180.00,0
26.2500,180.00,0
26.3000,180.00,0
26.3500,180.00,0
26.4000,180.00,0
26.4500,180.00,1
26.5000,180.00,5
26.5500,180.00,6
26.6000,180.00,75
26.6500,180.00,53
26.7000,180.00,48
26.7500,180.00,84
26.8000,180.00,117
26.8500,180.00,233
26.9000,180.00,750
26.9500,180.00,1291
27.0000,180.00,610
27.0500,180.00,133
27.1000,180.00,18
27.1500,180.00,7
27.2000,180.00,5
27.2500,180.00,1
27.3000,180.00,1
27.3500,180.00,0
27.4000,180.00,0
27.4500,180.00,1
27.5000,180.00,0
27.5500,180.00,0
27.6000,180.00,0
27.6500,180.00,1
27.7000,180.00,0
27.7500,180.00,0
27.8000,180.00,0
27.8500,180.00,0
27.9000,180.00,1
27.9500,180.00,0
28.0000,180.00,0
28.0500,180.00,0
28.1000,180.00,0
28.1500,180.00,0
28.2000,180.00,0
28.2500,180.00,0
28.3000,180.00,0
28.3500,180.00,0
28.4000,180.00,0
28.4500,180.00,0
28.5000,180.00,0
28.5500,180.00,0
28.6000,180.00,0
28.6500,180.00,0
28.7000,180.00,0
28.7500,180.00,0
25.8100,195.00,0
25.8600,195.00,0
25.9100,195.00,0
25.9600,195.00,0
26.0100,195.00,0
26.0600,195.00,0
26.1100,195.00,0
26.1600,195.00,0
26.2100,195.00,0
26.2600,195.00,0
26.3100,195.00,0
26.3600,195.00,0
26.4100,195.00,0
26.4600,195.00,1
26.5100,195.00,1
26.5600,195.00,0
26.6100,195.00,2
26.6600,195.00,3
26.7100,195.00,15
26.7600,195.00,31
26.8100,195.00,69
26.8600,195.00,159
26.9100,195.00,636
26.9600,195.00,1675
27.0100,195.00,565
27.0600,195.00,232
27.1100,195.00,108
27.1600,195.00,50
27.2100,195.00,35
27.2600,195.00,7
27.3100,195.00,1
27.3600,195.00,1
27.4100,195.00,0
27.4600,195.00,0
27.5100,195.00,0
27.5600,195.00,6
27.6100,195.00,1
27.6600,195.00,0
27.7100,195.00,0
27.7600,195.00,0
27.8100,195.00,0
27.8600,195.00,0
27.9100,195.00,0
27.9600,195.00,0
28.0100,195.00,0
28.0600,195.00,0
28.1100,195.00,0
28.1600,195.00,0
28.2100,195.00,0
28.2600,195.00,0
28.3100,195.00,0
28.3600,195.00,0
28.4100,195.00,0
28.4600,195.00,0
28.5100,195.00,0
28.5600,195.00,0
28.6100,195.00,0
28.6600,195.00,0
28.7100,195.00,0
28.7600,195.00,0
25.8200,210.00,0
25.8700,210.00,0
25.9200,210.00,0
25.9700,210.00,0
26.0200,210.00,0
26.0700,210.00,0
26.1200,210.00,0
26.1700,210.00,0
26.2200,210.00,0
26.2700,210.00,0
26.3200,210.00,0
26.3700,210.00,0
26.4200,210.00,0
26.4700,210.00,0
26.5200,210.00,1
26.5700,210.00,0
26.6200,210.00,1
26.6700,210.00,2
26.7200,210.00,1
26.7700,210.00,1
26.8200,210.00,4
26.8700,210.00,16
26.9200,210.00,101
26.9700,210.00,864
27.0200,210.00,1508
27.0700,210.00,531
27.1200,210.00,140
27.1700,210.00,296
27.2200,210.00,118
27.2700,210.00,21
27.3200,210.00,9
27.3700,210.00,22
27.4200,210.00,15
27.4700,210.00,10
27.5200,210.00,0
27.5700,210.00,0
27.6200,210.00,1
27.6700,210.00,6
27.7200,210.00,8
27.7700,210.00,1
27.8200,210.00,0
27.8700,210.00,0
27.9200,210.00,1
27.9700,210.00,2
28.0200,210.00,0
28.0700,210.00,0
28.1200,210.00,0
28.1700,210.00,0
28.2200,210.00,0
28.2700,210.00,0
28.3200,210.00,0
28.3700,210.00,0
28.4200,210.00,0
28.4700,210.00,0
28.5200,210.00,0
28.5700,210.00,0
28.6200,210.00,0
28.6700,210.00,0
28.7200,210.00,1
25.7800,225.00,0
25.8300,225.00,0
25.8800,225.00,0
25.9300,225.00,0
25.9800,225.00,0
26.0300,225.00,0
26.0800,225.00,0
26.1300,225.00,0
26.1800,225.00,0
26.2300,225.00,0
26.2800,225.00,0
26.3300,225.00,1
26.3800,225.00,0
26.4300,225.00,0
26.4800,225.00,0
26.5300,225.00,0
26.5800,225.00,1
26.6300,225.00,1
26.6800,225.00,0
26.7300,225.00,1
26.7800,225.00,3
26.8300,225.00,2
26.8800,225.00,5
26.9300,225.00,16
26.9800,225.00,89
27.0300,225.00,884
27.0800,225.00,1460
27.1300,225.00,562
27.1800,225.00,141
27.2300,225.00,124
27.2800,225.00,450
27.3300,225.00,165
27.3800,225.00,20
27.4300,225.00,4
27.4800,225.00,4
27.5300,225.00,3
27.5800,225.00,86
27.6300,225.00,17
27.6800,225.00,1
27.7300,225.00,1
27.7800,225.00,5
27.8300,225.00,1
27.8800,225.00,1
27.9300,225.00,2
27.9800,225.00,1
28.0300,225.00,2
28.0800,225.00,2
28.1300,225.00,3
28.1800,225.00,4
28.2300,225.00,1
28.2800,225.00,1
28.3300,225.00,1
28.3800,225.00,0
28.4300,225.00,0
28.4800,225.00,0
28.5300,225.00,0
28.5800,225.00,0
28.6300,225.00,0
28.6800,225.00,0
28.7300,225.00,0
25.7900,240.00,0
25.8400,240.00,0
25.8900,240.00,0
25.9400,240.00,0
25.9900,240.00,0
26.0400,240.00,0
26.0900,240.00,0
26.1400,240.00,0
26.1900,240.00,1
26.2400,240.00,0
26.2900,240.00,0
26.3400,240.00,0
26.3900,240.00,0
26.4400,240.00,0
26.4900,240.00,0
26.5400,240.00,0
26.5900,240.00,1
26.6400,240.00,0
26.6900,240.00,0
26.7400,240.00,2
26.7900,240.00,2
26.8400,240.00,1
26.8900,240.00,0
26.9400,240.00,7
26.9900,240.00,19
27.0400,240.00,64
27.0900,240.00,314
27.1400,240.00,1719
27.1900,240.00,641
27.2400,240.00,128
27.2900,240.00,100
27.3400,240.00,194
27.3900,240.00,413
27.4400,240.00,160
27.4900,240.00,16
27.5400,240.00,5
27.5900,240.00,1
27.6400,240.00,1
27.6900,240.00,7
27.7400,240.00,110
27.7900,240.00,9
27.8400,240.00,1
27.8900,240.00,1
27.9400,240.00,1
27.9900,240.00,0
28.0400,240.00,0
28.0900,240.00,0
28.1400,240.00,0
28.1900,240.00,0
28.2400,240.00,0
28.2900,240.00,0
28.3400,240.00,0
28.3900,240.00,0
28.4400,240.00,0
28.4900,240.00,0
28.5400,240.00,0
28.5900,240.00,0
28.6400,240.00,0
28.6900,240.00,0
28.7400,240.00,0
25.8000,255.00,0
25.8500,255.00,0
25.9000,255.00,0
25.9500,255.00,0
26.0000,255.00,0
26.0500,255.00,0
26.1000,255.00,0
26.1500,255.00,0
26.2000,255.00,0
26.2500,255.00,1
26.3000,255.00,0
26.3500,255.00,0
26.4000,255.00,0
26.4500,255.00,0
26.5000,255.00,1
26.5500,255.00,0
26.6000,255.00,0
26.6500,255.00,0
26.7000,255.00,1
26.7500,255.00,0
26.8000,255.00,0
26.8500,255.00,0
26.9000,255.00,2
26.9500,255.00,1
27.0000,255.00,0
27.0500,255.00,3
27.1000,255.00,26
27.1500,255.00,138
27.2000,255.00,1260
27.2500,255.00,686
27.3000,255.00,301
27.3500,255.00,58
27.4000,255.00,69
27.4500,255.00,286
27.5000,255.00,314
27.5500,255.00,117
27.6000,255.00,13
27.6500,255.00,1
27.7000,255.00,1
27.7500,255.00,0
27.8000,255.00,3
27.8500,255.00,17
27.9000,255.00,22
27.9500,255.00,12
28.0000,255.00,4
28.0500,255.00,0
28.1000,255.00,0
28.1500,255.00,0
28.2000,255.00,1
28.2500,255.00,0
28.3000,255.00,0
28.3500,255.00,0
28.4000,255.00,0
28.4500,255.00,0
28.5000,255.00,0
28.5500,255.00,0
28.6000,255.00,0
28.6500,255.00,0
28.7000,255.00,0
28.7500,255.00,0
25.8100,270.00,0
25.8600,270.00,0
25.9100,270.00,0
25.9600,270.00,0
26.0100,270.00,0
26.0600,270.00,0
26.1100,270.00,0
26.1600,270.00,0
26.2100,270.00,0
26.2600,270.00,0
26.3100,270.00,0
26.3600,270.00,0
26.4100,270.00,0
26.4600,270.00,0
26.5100,270.00,1
26.5600,270.00,0
26.6100,270.00,0
26.6600,270.00,0
26.7100,270.00,0
26.7600,270.00,0
26.8100,270.00,2
26.8600,270.00,0
26.9100,270.00,0
26.9600,270.00,0
27.0100,270.00,0
27.0600,270.00,1
27.1100,270.00,2
27.1600,270.00,5
27.2100,270.00,26
27.2600,270.00,374
27.3100,270.00,1197
27.3600,270.00,598
27.4100,270.00,233
27.4600,270.00,51
27.5100,270.00,82
27.5600,270.00,700
27.6100,270.00,236
27.6600,270.00,31
27.7100,270.00,4
27.7600,270.00,1
27.8100,270.00,2
27.8600,270.00,0
27.9100,270.00,3
27.9600,270.00,54
28.0100,270.00,9
28.0600,270.00,11
28.1100,270.00,0
28.1600,270.00,0
28.2100,270.00,0
28.2600,270.00,0
28.3100,270.00,0
28.3600,270.00,0
28.4100,270.00,0
28.4600,270.00,0
28.5100,270.00,0
28.5600,270.00,0
28.6100,270.00,0
28.6600,270.00,0
28.7100,270.00,0
28.7600,270.00,0
25.8200,285.00,0
25.8700,285.00,0
25.9200,285.00,1
25.9700,285.00,0
26.0200,285.00,0
26.0700,285.00,0
26.1200,285.00,0
26.1700,285.00,0
26.2200,285.00,0
26.2700,285.00,0
26.3200,285.00,0
26.3700,285.00,1
26.4200,285.00,0
26.4700,285.00,0
26.5200,285.00,0
26.5700,285.00,0
26.6200,285.00,0
26.6700,285.00,0
26.7200,285.00,0
26.7700,285.00,0
26.8200,285.00,1
26.8700,285.00,1
26.9200,285.00,0
26.9700,285.00,0
27.0200,285.00,0
27.0700,285.00,0
27.1200,285.00,2
27.1700,285.00,3
27.2200,285.00,5
27.2700,285.00,18
27.3200,285.00,116
27.3700,285.00,595
27.4200,285.00,946
27.4700,285.00,434
27.5200,285.00,136
27.5700,285.00,67
27.6200,285.00,507
27.6700,285.00,256
27.7200,285.00,70
27.7700,285.00,10
27.8200,285.00,2
27.8700,285.00,2
27.9200,285.00,0
27.9700,285.00,3
28.0200,285.00,84
28.0700,285.00,6
28.1200,285.00,8
28.1700,285.00,0
28.2200,285.00,1
28.2700,285.00,0
28.3200,285.00,0
28.3700,285.00,0
28.4200,285.00,0
28.4700,285.00,0
28.5200,285.00,0
28.5700,285.00,0
28.6200,285.00,0
28.6700,285.00,0
28.7200,285.00,0
25.7800,300.00,0
25.8300,300.00,0
25.8800,300.00,0
25.9300,300.00,0
25.9800,300.00,0
26.0300,300.00,0
26.0800,300.00,0
26.1300,300.00,0
26.1800,300.00,1
26.2300,300.00,0
26.2800,300.00,0
26.3300,300.00,0
26.3800,300.00,0
26.4300,300.00,0
26.4800,300.00,0
26.5300,300.00,0
26.5800,300.00,0
26.6300,300.00,0
26.6800,300.00,0
26.7300,300.00,0
26.7800,300.00,0
26.8300,300.00,0
26.8800,300.00,0
26.9300,300.00,0
26.9800,300.00,0
27.0300,300.00,1
27.0800,300.00,0
27.1300,300.00,0
27.1800,300.00,0
27.2300,300.00,1
27.2800,300.00,4
27.3300,300.00,16
27.3800,300.00,117
27.4300,300.00,422
27.4800,300.00,1321
27.5300,300.00,504
27.5800,300.00,268
27.6300,300.00,157
27.6800,300.00,729
27.7300,300.00,256
27.7800,300.00,45
27.8300,300.00,7
27.8800,300.00,12
27.9300,300.00,5
27.9800,300.00,7
28.0300,300.00,81
28.0800,300.00,18
28.1300,300.00,4
28.1800,300.00,3
28.2300,300.00,1
28.2800,300.00,0
28.3300,300.00,1
28.3800,300.00,0
28.4300,300.00,0
28.4800,300.00,0
28.5300,300.00,0
28.5800,300.00,0
28.6300,300.00,0
28.6800,300.00,0
28.7300,300.00,1
25.7900,315.00,0
25.8400,315.00,0
25.8900,315.00,0
25.9400,315.00,0
25.9900,315.00,0
26.0400,315.00,0
26.0900,315.00,0
26.1400,315.00,0
26.1900,315.00,0
26.2400,315.00,0
26.2900,315.00,0
26.3400,315.00,0
26.3900,315.00,0
26.4400,315.00,0
26.4900,315.00,0
26.5400,315.00,0
26.5900,315.00,0
26.6400,315.00,0
26.6900,315.00,1
26.7400,315.00,0
26.7900,315.00,0
26.8400,315.00,0
26.8900,315.00,0
26.9400,315.00,0
26.9900,315.00,0
27.0400,315.00,0
27.0900,315.00,1
27.1400,315.00,7
27.1900,315.00,49
27.2400,315.00,48
27.2900,315.00,11
27.3400,315.00,5
27.3900,315.00,12
27.4400,315.00,68
27.4900,315.00,510
27.5400,315.00,579
27.5900,315.00,600
27.6400,315.00,376
27.6900,315.00,578
27.7400,315.00,544
27.7900,315.00,246
27.8400,315.00,100
27.8900,315.00,35
27.9400,315.00,9
27.9900,315.00,74
28.0400,315.00,16
28.0900,315.00,7
28.1400,315.00,1
28.1900,315.00,0
28.2400,315.00,0
28.2900,315.00,0
28.3400,315.00,2
28.3900,315.00,0
28.4400,315.00,0
28.4900,315.00,0
28.5400,315.00,0
28.5900,315.00,0
28.6400,315.00,0
28.6900,315.00,0
28.7400,315.00,0
25.8000,330.00,0
25.8500,330.00,0
25.9000,330.00,0
25.9500,330.00,0
26.0000,330.00,0
26.0500,330.00,0
26.1000,330.00,0
26.1500,330.00,0
26.2000,330.00,0
26.2500,330.00,0
26.3000,330.00,0
26.3500,330.00,0
26.4000,330.00,0
26.4500,330.00,0
26.5000,330.00,0
26.5500,330.00,0
26.6000,330.00,0
26.6500,330.00,1
26.7000,330.00,0
26.7500,330.00,0
26.8000,330.00,1
26.8500,330.00,3
26.9000,330.00,1
26.9500,330.00,3
27.0000,330.00,13
27.0500,330.00,26
27.1000,330.00,19
27.1500,330.00,15
27.2000,330.00,45
27.2500,330.00,93
27.3000,330.00,41
27.3500,330.00,16
27.4000,330.00,6
27.4500,330.00,7
27.5000,330.00,52
27.5500,330.00,270
27.6000,330.00,514
27.6500,330.00,769
27.7000,330.00,717
27.7500,330.00,681
27.8000,330.00,329
27.8500,330.00,156
27.9000,330.00,81
27.9500,330.00,48
28.0000,330.00,35
28.0500,330.00,13
28.1000,330.00,4
28.1500,330.00,2
28.2000,330.00,1
28.2500,330.00,1
28.3000,330.00,0
28.3500,330.00,0
28.4000,330.00,1
28.4500,330.00,1
28.5000,330.00,0
28.5500,330.00,0
28.6000,330.00,0
28.6500,330.00,0
28.7000,330.00,0
28.7500,330.00,0
25.8100,345.00,0
25.8600,345.00,0
25.9100,345.00,0
25.9600,345.00,0
26.0100,345.00,0
26.0600,345.00,0
26.1100,345.00,0
26.1600,345.00,0
26.2100,345.00,0
26.2600,345.00,0
26.3100,345.00,0
26.3600,345.00,0
26.4100,345.00,1
26.4600,345.00,0
26.5100,345.00,0
26.5600,345.00,0
26.6100,345.00,0
26.6600,345.00,0
26.7100,345.00,1
26.7600,345.00,0
26.8100,345.00,0
26.8600,345.00,2
26.9100,345.00,2
26.9600,345.00,12
27.0100,345.00,30
27.0600,345.00,27
27.1100,345.00,31
27.1600,345.00,19
27.2100,345.00,34
27.2600,345.00,58
27.3100,345.00,80
27.3600,345.00,22
27.4100,345.00,8
27.4600,345.00,8
27.5100,345.00,17
27.5600,345.00,76
27.6100,345.00,179
27.6600,345.00,544
27.7100,345.00,947
27.7600,345.00,570
27.8100,345.00,299
27.8600,345.00,169
27.9100,345.00,87
27.9600,345.00,35
28.0100,345.00,10
28.0600,345.00,8
28.1100,345.00,18
28.1600,345.00,50
28.2100,345.00,63
28.2600,345.00,11
28.3100,345.00,4
28.3600,345.00,0
28.4100,345.00,1
28.4600,345.00,0
28.5100,345.00,0
28.5600,345.00,0
28.6100,345.00,0
28.6600,345.00,1
28.7100,345.00,0
28.7600,345.00,0